[ 2023-08-12 11:08:38,453 ] 187 werkzeug - INFO - [31m[1mWARNING: This is a development server. Do not use it in a production deployment. Use a production WSGI server instead.[0m
 * Running on all addresses (0.0.0.0)
 * Running on http://127.0.0.1:5000
 * Running on http://127.0.0.1:5000
[ 2023-08-12 11:08:38,453 ] 187 werkzeug - INFO - [33mPress CTRL+C to quit[0m
[ 2023-08-12 11:08:54,144 ] 1414 app - ERROR - Exception on / [GET]
Traceback (most recent call last):
  File "C:\Users\bhara\anaconda3\envs\env\lib\site-packages\flask\app.py", line 2190, in wsgi_app
    response = self.full_dispatch_request()
  File "C:\Users\bhara\anaconda3\envs\env\lib\site-packages\flask\app.py", line 1486, in full_dispatch_request
    rv = self.handle_user_exception(e)
  File "C:\Users\bhara\anaconda3\envs\env\lib\site-packages\flask\app.py", line 1484, in full_dispatch_request
    rv = self.dispatch_request()
  File "C:\Users\bhara\anaconda3\envs\env\lib\site-packages\flask\app.py", line 1469, in dispatch_request
    return self.ensure_sync(self.view_functions[rule.endpoint])(**view_args)
  File "app.py", line 12, in index
    return render_template('index.html')
  File "C:\Users\bhara\anaconda3\envs\env\lib\site-packages\flask\templating.py", line 151, in render_template
    return _render(app, template, context)
  File "C:\Users\bhara\anaconda3\envs\env\lib\site-packages\flask\templating.py", line 132, in _render
    rv = template.render(context)
  File "C:\Users\bhara\anaconda3\envs\env\lib\site-packages\jinja2\environment.py", line 1301, in render
    self.environment.handle_exception()
  File "C:\Users\bhara\anaconda3\envs\env\lib\site-packages\jinja2\environment.py", line 936, in handle_exception
    raise rewrite_traceback_stack(source=source)
  File "C:\Users\bhara\Downloads\newproject car modular1\templates\index.html", line 6, in top-level template code
    <form action="{{ url_for('predictdata')}}" method="post">
  File "C:\Users\bhara\anaconda3\envs\env\lib\site-packages\flask\app.py", line 1697, in url_for
    return self.handle_url_build_error(error, endpoint, values)
  File "C:\Users\bhara\anaconda3\envs\env\lib\site-packages\flask\app.py", line 1686, in url_for
    rv = url_adapter.build(  # type: ignore[union-attr]
  File "C:\Users\bhara\anaconda3\envs\env\lib\site-packages\werkzeug\routing\map.py", line 950, in build
    raise BuildError(endpoint, values, method, self)
werkzeug.routing.exceptions.BuildError: Could not build url for endpoint 'predictdata'. Did you mean 'predict_datapoint' instead?
[ 2023-08-12 11:08:54,534 ] 187 werkzeug - INFO - 127.0.0.1 - - [12/Aug/2023 11:08:54] "[35m[1mGET / HTTP/1.1[0m" 500 -
[ 2023-08-12 11:08:54,848 ] 1414 app - ERROR - Exception on / [GET]
Traceback (most recent call last):
  File "C:\Users\bhara\anaconda3\envs\env\lib\site-packages\flask\app.py", line 2190, in wsgi_app
    response = self.full_dispatch_request()
  File "C:\Users\bhara\anaconda3\envs\env\lib\site-packages\flask\app.py", line 1486, in full_dispatch_request
    rv = self.handle_user_exception(e)
  File "C:\Users\bhara\anaconda3\envs\env\lib\site-packages\flask\app.py", line 1484, in full_dispatch_request
    rv = self.dispatch_request()
  File "C:\Users\bhara\anaconda3\envs\env\lib\site-packages\flask\app.py", line 1469, in dispatch_request
    return self.ensure_sync(self.view_functions[rule.endpoint])(**view_args)
  File "app.py", line 12, in index
    return render_template('index.html')
  File "C:\Users\bhara\anaconda3\envs\env\lib\site-packages\flask\templating.py", line 151, in render_template
    return _render(app, template, context)
  File "C:\Users\bhara\anaconda3\envs\env\lib\site-packages\flask\templating.py", line 132, in _render
    rv = template.render(context)
  File "C:\Users\bhara\anaconda3\envs\env\lib\site-packages\jinja2\environment.py", line 1301, in render
    self.environment.handle_exception()
  File "C:\Users\bhara\anaconda3\envs\env\lib\site-packages\jinja2\environment.py", line 936, in handle_exception
    raise rewrite_traceback_stack(source=source)
  File "C:\Users\bhara\Downloads\newproject car modular1\templates\index.html", line 6, in top-level template code
    <form action="{{ url_for('predictdata')}}" method="post">
  File "C:\Users\bhara\anaconda3\envs\env\lib\site-packages\flask\app.py", line 1697, in url_for
    return self.handle_url_build_error(error, endpoint, values)
  File "C:\Users\bhara\anaconda3\envs\env\lib\site-packages\flask\app.py", line 1686, in url_for
    rv = url_adapter.build(  # type: ignore[union-attr]
  File "C:\Users\bhara\anaconda3\envs\env\lib\site-packages\werkzeug\routing\map.py", line 950, in build
    raise BuildError(endpoint, values, method, self)
werkzeug.routing.exceptions.BuildError: Could not build url for endpoint 'predictdata'. Did you mean 'predict_datapoint' instead?
[ 2023-08-12 11:08:54,857 ] 187 werkzeug - INFO - 127.0.0.1 - - [12/Aug/2023 11:08:54] "[35m[1mGET / HTTP/1.1[0m" 500 -
[ 2023-08-12 11:08:55,345 ] 187 werkzeug - INFO - 127.0.0.1 - - [12/Aug/2023 11:08:55] "[33mGET /favicon.ico HTTP/1.1[0m" 404 -
[ 2023-08-12 11:10:38,254 ] 1414 app - ERROR - Exception on / [GET]
Traceback (most recent call last):
  File "C:\Users\bhara\anaconda3\envs\env\lib\site-packages\flask\app.py", line 2190, in wsgi_app
    response = self.full_dispatch_request()
  File "C:\Users\bhara\anaconda3\envs\env\lib\site-packages\flask\app.py", line 1486, in full_dispatch_request
    rv = self.handle_user_exception(e)
  File "C:\Users\bhara\anaconda3\envs\env\lib\site-packages\flask\app.py", line 1484, in full_dispatch_request
    rv = self.dispatch_request()
  File "C:\Users\bhara\anaconda3\envs\env\lib\site-packages\flask\app.py", line 1469, in dispatch_request
    return self.ensure_sync(self.view_functions[rule.endpoint])(**view_args)
  File "app.py", line 12, in index
  File "C:\Users\bhara\anaconda3\envs\env\lib\site-packages\flask\templating.py", line 151, in render_template
    return _render(app, template, context)
  File "C:\Users\bhara\anaconda3\envs\env\lib\site-packages\flask\templating.py", line 132, in _render
    rv = template.render(context)
  File "C:\Users\bhara\anaconda3\envs\env\lib\site-packages\jinja2\environment.py", line 1301, in render
    self.environment.handle_exception()
  File "C:\Users\bhara\anaconda3\envs\env\lib\site-packages\jinja2\environment.py", line 936, in handle_exception
    raise rewrite_traceback_stack(source=source)
  File "C:\Users\bhara\Downloads\newproject car modular1\templates\index.html", line 6, in top-level template code
    <form action="{{ url_for('predictdata')}}" method="post">
  File "C:\Users\bhara\anaconda3\envs\env\lib\site-packages\flask\app.py", line 1697, in url_for
    return self.handle_url_build_error(error, endpoint, values)
  File "C:\Users\bhara\anaconda3\envs\env\lib\site-packages\flask\app.py", line 1686, in url_for
    rv = url_adapter.build(  # type: ignore[union-attr]
  File "C:\Users\bhara\anaconda3\envs\env\lib\site-packages\werkzeug\routing\map.py", line 950, in build
    raise BuildError(endpoint, values, method, self)
werkzeug.routing.exceptions.BuildError: Could not build url for endpoint 'predictdata'. Did you mean 'predict_datapoint' instead?
[ 2023-08-12 11:10:38,263 ] 187 werkzeug - INFO - 127.0.0.1 - - [12/Aug/2023 11:10:38] "[35m[1mGET / HTTP/1.1[0m" 500 -
[ 2023-08-12 11:10:39,817 ] 1414 app - ERROR - Exception on / [GET]
Traceback (most recent call last):
  File "C:\Users\bhara\anaconda3\envs\env\lib\site-packages\flask\app.py", line 2190, in wsgi_app
    response = self.full_dispatch_request()
  File "C:\Users\bhara\anaconda3\envs\env\lib\site-packages\flask\app.py", line 1486, in full_dispatch_request
    rv = self.handle_user_exception(e)
  File "C:\Users\bhara\anaconda3\envs\env\lib\site-packages\flask\app.py", line 1484, in full_dispatch_request
    rv = self.dispatch_request()
  File "C:\Users\bhara\anaconda3\envs\env\lib\site-packages\flask\app.py", line 1469, in dispatch_request
    return self.ensure_sync(self.view_functions[rule.endpoint])(**view_args)
  File "app.py", line 12, in index
  File "C:\Users\bhara\anaconda3\envs\env\lib\site-packages\flask\templating.py", line 151, in render_template
    return _render(app, template, context)
  File "C:\Users\bhara\anaconda3\envs\env\lib\site-packages\flask\templating.py", line 132, in _render
    rv = template.render(context)
  File "C:\Users\bhara\anaconda3\envs\env\lib\site-packages\jinja2\environment.py", line 1301, in render
    self.environment.handle_exception()
  File "C:\Users\bhara\anaconda3\envs\env\lib\site-packages\jinja2\environment.py", line 936, in handle_exception
    raise rewrite_traceback_stack(source=source)
  File "C:\Users\bhara\Downloads\newproject car modular1\templates\index.html", line 6, in top-level template code
    <form action="{{ url_for('predictdata')}}" method="post">
  File "C:\Users\bhara\anaconda3\envs\env\lib\site-packages\flask\app.py", line 1697, in url_for
    return self.handle_url_build_error(error, endpoint, values)
  File "C:\Users\bhara\anaconda3\envs\env\lib\site-packages\flask\app.py", line 1686, in url_for
    rv = url_adapter.build(  # type: ignore[union-attr]
  File "C:\Users\bhara\anaconda3\envs\env\lib\site-packages\werkzeug\routing\map.py", line 950, in build
    raise BuildError(endpoint, values, method, self)
werkzeug.routing.exceptions.BuildError: Could not build url for endpoint 'predictdata'. Did you mean 'predict_datapoint' instead?
[ 2023-08-12 11:10:39,821 ] 187 werkzeug - INFO - 127.0.0.1 - - [12/Aug/2023 11:10:39] "[35m[1mGET / HTTP/1.1[0m" 500 -
[ 2023-08-12 11:10:40,111 ] 1414 app - ERROR - Exception on / [GET]
Traceback (most recent call last):
  File "C:\Users\bhara\anaconda3\envs\env\lib\site-packages\flask\app.py", line 2190, in wsgi_app
    response = self.full_dispatch_request()
  File "C:\Users\bhara\anaconda3\envs\env\lib\site-packages\flask\app.py", line 1486, in full_dispatch_request
    rv = self.handle_user_exception(e)
  File "C:\Users\bhara\anaconda3\envs\env\lib\site-packages\flask\app.py", line 1484, in full_dispatch_request
    rv = self.dispatch_request()
  File "C:\Users\bhara\anaconda3\envs\env\lib\site-packages\flask\app.py", line 1469, in dispatch_request
    return self.ensure_sync(self.view_functions[rule.endpoint])(**view_args)
  File "app.py", line 12, in index
  File "C:\Users\bhara\anaconda3\envs\env\lib\site-packages\flask\templating.py", line 151, in render_template
    return _render(app, template, context)
  File "C:\Users\bhara\anaconda3\envs\env\lib\site-packages\flask\templating.py", line 132, in _render
    rv = template.render(context)
  File "C:\Users\bhara\anaconda3\envs\env\lib\site-packages\jinja2\environment.py", line 1301, in render
    self.environment.handle_exception()
  File "C:\Users\bhara\anaconda3\envs\env\lib\site-packages\jinja2\environment.py", line 936, in handle_exception
    raise rewrite_traceback_stack(source=source)
  File "C:\Users\bhara\Downloads\newproject car modular1\templates\index.html", line 6, in top-level template code
    <form action="{{ url_for('predictdata')}}" method="post">
  File "C:\Users\bhara\anaconda3\envs\env\lib\site-packages\flask\app.py", line 1697, in url_for
    return self.handle_url_build_error(error, endpoint, values)
  File "C:\Users\bhara\anaconda3\envs\env\lib\site-packages\flask\app.py", line 1686, in url_for
    rv = url_adapter.build(  # type: ignore[union-attr]
  File "C:\Users\bhara\anaconda3\envs\env\lib\site-packages\werkzeug\routing\map.py", line 950, in build
    raise BuildError(endpoint, values, method, self)
werkzeug.routing.exceptions.BuildError: Could not build url for endpoint 'predictdata'. Did you mean 'predict_datapoint' instead?
[ 2023-08-12 11:10:40,111 ] 187 werkzeug - INFO - 127.0.0.1 - - [12/Aug/2023 11:10:40] "[35m[1mGET / HTTP/1.1[0m" 500 -
[ 2023-08-12 11:10:40,201 ] 1414 app - ERROR - Exception on / [GET]
Traceback (most recent call last):
  File "C:\Users\bhara\anaconda3\envs\env\lib\site-packages\flask\app.py", line 2190, in wsgi_app
    response = self.full_dispatch_request()
  File "C:\Users\bhara\anaconda3\envs\env\lib\site-packages\flask\app.py", line 1486, in full_dispatch_request
    rv = self.handle_user_exception(e)
  File "C:\Users\bhara\anaconda3\envs\env\lib\site-packages\flask\app.py", line 1484, in full_dispatch_request
    rv = self.dispatch_request()
  File "C:\Users\bhara\anaconda3\envs\env\lib\site-packages\flask\app.py", line 1469, in dispatch_request
    return self.ensure_sync(self.view_functions[rule.endpoint])(**view_args)
  File "app.py", line 12, in index
  File "C:\Users\bhara\anaconda3\envs\env\lib\site-packages\flask\templating.py", line 151, in render_template
    return _render(app, template, context)
  File "C:\Users\bhara\anaconda3\envs\env\lib\site-packages\flask\templating.py", line 132, in _render
    rv = template.render(context)
  File "C:\Users\bhara\anaconda3\envs\env\lib\site-packages\jinja2\environment.py", line 1301, in render
    self.environment.handle_exception()
  File "C:\Users\bhara\anaconda3\envs\env\lib\site-packages\jinja2\environment.py", line 936, in handle_exception
    raise rewrite_traceback_stack(source=source)
  File "C:\Users\bhara\Downloads\newproject car modular1\templates\index.html", line 6, in top-level template code
    <form action="{{ url_for('predictdata')}}" method="post">
  File "C:\Users\bhara\anaconda3\envs\env\lib\site-packages\flask\app.py", line 1697, in url_for
    return self.handle_url_build_error(error, endpoint, values)
  File "C:\Users\bhara\anaconda3\envs\env\lib\site-packages\flask\app.py", line 1686, in url_for
    rv = url_adapter.build(  # type: ignore[union-attr]
  File "C:\Users\bhara\anaconda3\envs\env\lib\site-packages\werkzeug\routing\map.py", line 950, in build
    raise BuildError(endpoint, values, method, self)
werkzeug.routing.exceptions.BuildError: Could not build url for endpoint 'predictdata'. Did you mean 'predict_datapoint' instead?
[ 2023-08-12 11:10:40,201 ] 187 werkzeug - INFO - 127.0.0.1 - - [12/Aug/2023 11:10:40] "[35m[1mGET / HTTP/1.1[0m" 500 -
[ 2023-08-12 11:10:40,423 ] 1414 app - ERROR - Exception on / [GET]
Traceback (most recent call last):
  File "C:\Users\bhara\anaconda3\envs\env\lib\site-packages\flask\app.py", line 2190, in wsgi_app
    response = self.full_dispatch_request()
  File "C:\Users\bhara\anaconda3\envs\env\lib\site-packages\flask\app.py", line 1486, in full_dispatch_request
    rv = self.handle_user_exception(e)
  File "C:\Users\bhara\anaconda3\envs\env\lib\site-packages\flask\app.py", line 1484, in full_dispatch_request
    rv = self.dispatch_request()
  File "C:\Users\bhara\anaconda3\envs\env\lib\site-packages\flask\app.py", line 1469, in dispatch_request
    return self.ensure_sync(self.view_functions[rule.endpoint])(**view_args)
  File "app.py", line 12, in index
  File "C:\Users\bhara\anaconda3\envs\env\lib\site-packages\flask\templating.py", line 151, in render_template
    return _render(app, template, context)
  File "C:\Users\bhara\anaconda3\envs\env\lib\site-packages\flask\templating.py", line 132, in _render
    rv = template.render(context)
  File "C:\Users\bhara\anaconda3\envs\env\lib\site-packages\jinja2\environment.py", line 1301, in render
    self.environment.handle_exception()
  File "C:\Users\bhara\anaconda3\envs\env\lib\site-packages\jinja2\environment.py", line 936, in handle_exception
    raise rewrite_traceback_stack(source=source)
  File "C:\Users\bhara\Downloads\newproject car modular1\templates\index.html", line 6, in top-level template code
    <form action="{{ url_for('predictdata')}}" method="post">
  File "C:\Users\bhara\anaconda3\envs\env\lib\site-packages\flask\app.py", line 1697, in url_for
    return self.handle_url_build_error(error, endpoint, values)
  File "C:\Users\bhara\anaconda3\envs\env\lib\site-packages\flask\app.py", line 1686, in url_for
    rv = url_adapter.build(  # type: ignore[union-attr]
  File "C:\Users\bhara\anaconda3\envs\env\lib\site-packages\werkzeug\routing\map.py", line 950, in build
    raise BuildError(endpoint, values, method, self)
werkzeug.routing.exceptions.BuildError: Could not build url for endpoint 'predictdata'. Did you mean 'predict_datapoint' instead?
[ 2023-08-12 11:10:40,423 ] 187 werkzeug - INFO - 127.0.0.1 - - [12/Aug/2023 11:10:40] "[35m[1mGET / HTTP/1.1[0m" 500 -
[ 2023-08-12 11:10:40,715 ] 1414 app - ERROR - Exception on / [GET]
Traceback (most recent call last):
  File "C:\Users\bhara\anaconda3\envs\env\lib\site-packages\flask\app.py", line 2190, in wsgi_app
    response = self.full_dispatch_request()
  File "C:\Users\bhara\anaconda3\envs\env\lib\site-packages\flask\app.py", line 1486, in full_dispatch_request
    rv = self.handle_user_exception(e)
  File "C:\Users\bhara\anaconda3\envs\env\lib\site-packages\flask\app.py", line 1484, in full_dispatch_request
    rv = self.dispatch_request()
  File "C:\Users\bhara\anaconda3\envs\env\lib\site-packages\flask\app.py", line 1469, in dispatch_request
    return self.ensure_sync(self.view_functions[rule.endpoint])(**view_args)
  File "app.py", line 12, in index
  File "C:\Users\bhara\anaconda3\envs\env\lib\site-packages\flask\templating.py", line 151, in render_template
    return _render(app, template, context)
  File "C:\Users\bhara\anaconda3\envs\env\lib\site-packages\flask\templating.py", line 132, in _render
    rv = template.render(context)
  File "C:\Users\bhara\anaconda3\envs\env\lib\site-packages\jinja2\environment.py", line 1301, in render
    self.environment.handle_exception()
  File "C:\Users\bhara\anaconda3\envs\env\lib\site-packages\jinja2\environment.py", line 936, in handle_exception
    raise rewrite_traceback_stack(source=source)
  File "C:\Users\bhara\Downloads\newproject car modular1\templates\index.html", line 6, in top-level template code
    <form action="{{ url_for('predictdata')}}" method="post">
  File "C:\Users\bhara\anaconda3\envs\env\lib\site-packages\flask\app.py", line 1697, in url_for
    return self.handle_url_build_error(error, endpoint, values)
  File "C:\Users\bhara\anaconda3\envs\env\lib\site-packages\flask\app.py", line 1686, in url_for
    rv = url_adapter.build(  # type: ignore[union-attr]
  File "C:\Users\bhara\anaconda3\envs\env\lib\site-packages\werkzeug\routing\map.py", line 950, in build
    raise BuildError(endpoint, values, method, self)
werkzeug.routing.exceptions.BuildError: Could not build url for endpoint 'predictdata'. Did you mean 'predict_datapoint' instead?
[ 2023-08-12 11:10:40,717 ] 187 werkzeug - INFO - 127.0.0.1 - - [12/Aug/2023 11:10:40] "[35m[1mGET / HTTP/1.1[0m" 500 -
[ 2023-08-12 11:11:18,485 ] 1414 app - ERROR - Exception on /predictdata [GET]
Traceback (most recent call last):
  File "C:\Users\bhara\anaconda3\envs\env\lib\site-packages\flask\app.py", line 2190, in wsgi_app
    response = self.full_dispatch_request()
  File "C:\Users\bhara\anaconda3\envs\env\lib\site-packages\flask\app.py", line 1486, in full_dispatch_request
    rv = self.handle_user_exception(e)
  File "C:\Users\bhara\anaconda3\envs\env\lib\site-packages\flask\app.py", line 1484, in full_dispatch_request
    rv = self.dispatch_request()
  File "C:\Users\bhara\anaconda3\envs\env\lib\site-packages\flask\app.py", line 1469, in dispatch_request
    return self.ensure_sync(self.view_functions[rule.endpoint])(**view_args)
  File "app.py", line 17, in predict_datapoint
    else:
  File "C:\Users\bhara\anaconda3\envs\env\lib\site-packages\flask\templating.py", line 151, in render_template
    return _render(app, template, context)
  File "C:\Users\bhara\anaconda3\envs\env\lib\site-packages\flask\templating.py", line 132, in _render
    rv = template.render(context)
  File "C:\Users\bhara\anaconda3\envs\env\lib\site-packages\jinja2\environment.py", line 1301, in render
    self.environment.handle_exception()
  File "C:\Users\bhara\anaconda3\envs\env\lib\site-packages\jinja2\environment.py", line 936, in handle_exception
    raise rewrite_traceback_stack(source=source)
  File "C:\Users\bhara\Downloads\newproject car modular1\templates\index.html", line 6, in top-level template code
    <form action="{{ url_for('predictdata')}}" method="post">
  File "C:\Users\bhara\anaconda3\envs\env\lib\site-packages\flask\app.py", line 1697, in url_for
    return self.handle_url_build_error(error, endpoint, values)
  File "C:\Users\bhara\anaconda3\envs\env\lib\site-packages\flask\app.py", line 1686, in url_for
    rv = url_adapter.build(  # type: ignore[union-attr]
  File "C:\Users\bhara\anaconda3\envs\env\lib\site-packages\werkzeug\routing\map.py", line 950, in build
    raise BuildError(endpoint, values, method, self)
werkzeug.routing.exceptions.BuildError: Could not build url for endpoint 'predictdata'. Did you mean 'predict_datapoint' instead?
[ 2023-08-12 11:11:18,486 ] 187 werkzeug - INFO - 127.0.0.1 - - [12/Aug/2023 11:11:18] "[35m[1mGET /predictdata HTTP/1.1[0m" 500 -
[ 2023-08-12 11:11:20,754 ] 1414 app - ERROR - Exception on /predictdata [GET]
Traceback (most recent call last):
  File "C:\Users\bhara\anaconda3\envs\env\lib\site-packages\flask\app.py", line 2190, in wsgi_app
    response = self.full_dispatch_request()
  File "C:\Users\bhara\anaconda3\envs\env\lib\site-packages\flask\app.py", line 1486, in full_dispatch_request
    rv = self.handle_user_exception(e)
  File "C:\Users\bhara\anaconda3\envs\env\lib\site-packages\flask\app.py", line 1484, in full_dispatch_request
    rv = self.dispatch_request()
  File "C:\Users\bhara\anaconda3\envs\env\lib\site-packages\flask\app.py", line 1469, in dispatch_request
    return self.ensure_sync(self.view_functions[rule.endpoint])(**view_args)
  File "app.py", line 17, in predict_datapoint
    else:
  File "C:\Users\bhara\anaconda3\envs\env\lib\site-packages\flask\templating.py", line 151, in render_template
    return _render(app, template, context)
  File "C:\Users\bhara\anaconda3\envs\env\lib\site-packages\flask\templating.py", line 132, in _render
    rv = template.render(context)
  File "C:\Users\bhara\anaconda3\envs\env\lib\site-packages\jinja2\environment.py", line 1301, in render
    self.environment.handle_exception()
  File "C:\Users\bhara\anaconda3\envs\env\lib\site-packages\jinja2\environment.py", line 936, in handle_exception
    raise rewrite_traceback_stack(source=source)
  File "C:\Users\bhara\Downloads\newproject car modular1\templates\index.html", line 6, in top-level template code
    <form action="{{ url_for('predictdata')}}" method="post">
  File "C:\Users\bhara\anaconda3\envs\env\lib\site-packages\flask\app.py", line 1697, in url_for
    return self.handle_url_build_error(error, endpoint, values)
  File "C:\Users\bhara\anaconda3\envs\env\lib\site-packages\flask\app.py", line 1686, in url_for
    rv = url_adapter.build(  # type: ignore[union-attr]
  File "C:\Users\bhara\anaconda3\envs\env\lib\site-packages\werkzeug\routing\map.py", line 950, in build
    raise BuildError(endpoint, values, method, self)
werkzeug.routing.exceptions.BuildError: Could not build url for endpoint 'predictdata'. Did you mean 'predict_datapoint' instead?
[ 2023-08-12 11:11:20,756 ] 187 werkzeug - INFO - 127.0.0.1 - - [12/Aug/2023 11:11:20] "[35m[1mGET /predictdata HTTP/1.1[0m" 500 -
[ 2023-08-12 11:11:28,198 ] 1414 app - ERROR - Exception on / [GET]
Traceback (most recent call last):
  File "C:\Users\bhara\anaconda3\envs\env\lib\site-packages\flask\app.py", line 2190, in wsgi_app
    response = self.full_dispatch_request()
  File "C:\Users\bhara\anaconda3\envs\env\lib\site-packages\flask\app.py", line 1486, in full_dispatch_request
    rv = self.handle_user_exception(e)
  File "C:\Users\bhara\anaconda3\envs\env\lib\site-packages\flask\app.py", line 1484, in full_dispatch_request
    rv = self.dispatch_request()
  File "C:\Users\bhara\anaconda3\envs\env\lib\site-packages\flask\app.py", line 1469, in dispatch_request
    return self.ensure_sync(self.view_functions[rule.endpoint])(**view_args)
  File "app.py", line 12, in index
  File "C:\Users\bhara\anaconda3\envs\env\lib\site-packages\flask\templating.py", line 151, in render_template
    return _render(app, template, context)
  File "C:\Users\bhara\anaconda3\envs\env\lib\site-packages\flask\templating.py", line 132, in _render
    rv = template.render(context)
  File "C:\Users\bhara\anaconda3\envs\env\lib\site-packages\jinja2\environment.py", line 1301, in render
    self.environment.handle_exception()
  File "C:\Users\bhara\anaconda3\envs\env\lib\site-packages\jinja2\environment.py", line 936, in handle_exception
    raise rewrite_traceback_stack(source=source)
  File "C:\Users\bhara\Downloads\newproject car modular1\templates\index.html", line 6, in top-level template code
    <form action="{{ url_for('predictdata')}}" method="post">
  File "C:\Users\bhara\anaconda3\envs\env\lib\site-packages\flask\app.py", line 1697, in url_for
    return self.handle_url_build_error(error, endpoint, values)
  File "C:\Users\bhara\anaconda3\envs\env\lib\site-packages\flask\app.py", line 1686, in url_for
    rv = url_adapter.build(  # type: ignore[union-attr]
  File "C:\Users\bhara\anaconda3\envs\env\lib\site-packages\werkzeug\routing\map.py", line 950, in build
    raise BuildError(endpoint, values, method, self)
werkzeug.routing.exceptions.BuildError: Could not build url for endpoint 'predictdata'. Did you mean 'predict_datapoint' instead?
[ 2023-08-12 11:11:28,203 ] 187 werkzeug - INFO - 127.0.0.1 - - [12/Aug/2023 11:11:28] "[35m[1mGET / HTTP/1.1[0m" 500 -
