[ 2023-08-12 11:25:24,358 ] 187 werkzeug - INFO - [31m[1mWARNING: This is a development server. Do not use it in a production deployment. Use a production WSGI server instead.[0m
 * Running on all addresses (0.0.0.0)
 * Running on http://127.0.0.1:5000
 * Running on http://192.168.43.75:5000
[ 2023-08-12 11:25:24,358 ] 187 werkzeug - INFO - [33mPress CTRL+C to quit[0m
[ 2023-08-12 11:25:36,874 ] 1414 app - ERROR - Exception on / [GET]
Traceback (most recent call last):
  File "C:\Users\bhara\anaconda3\envs\env\lib\site-packages\flask\app.py", line 2190, in wsgi_app
    response = self.full_dispatch_request()
  File "C:\Users\bhara\anaconda3\envs\env\lib\site-packages\flask\app.py", line 1486, in full_dispatch_request
    rv = self.handle_user_exception(e)
  File "C:\Users\bhara\anaconda3\envs\env\lib\site-packages\flask\app.py", line 1484, in full_dispatch_request
    rv = self.dispatch_request()
  File "C:\Users\bhara\anaconda3\envs\env\lib\site-packages\flask\app.py", line 1469, in dispatch_request
    return self.ensure_sync(self.view_functions[rule.endpoint])(**view_args)
  File "app.py", line 11, in index
    return render_template('index.html')
  File "C:\Users\bhara\anaconda3\envs\env\lib\site-packages\flask\templating.py", line 151, in render_template
    return _render(app, template, context)
  File "C:\Users\bhara\anaconda3\envs\env\lib\site-packages\flask\templating.py", line 132, in _render
    rv = template.render(context)
  File "C:\Users\bhara\anaconda3\envs\env\lib\site-packages\jinja2\environment.py", line 1301, in render
    self.environment.handle_exception()
  File "C:\Users\bhara\anaconda3\envs\env\lib\site-packages\jinja2\environment.py", line 936, in handle_exception
    raise rewrite_traceback_stack(source=source)
  File "C:\Users\bhara\Downloads\newproject car modular1\templates\index.html", line 6, in top-level template code
    <form action="{{ url_for('predictdata')}}" method="post">
  File "C:\Users\bhara\anaconda3\envs\env\lib\site-packages\flask\app.py", line 1697, in url_for
    return self.handle_url_build_error(error, endpoint, values)
  File "C:\Users\bhara\anaconda3\envs\env\lib\site-packages\flask\app.py", line 1686, in url_for
    rv = url_adapter.build(  # type: ignore[union-attr]
  File "C:\Users\bhara\anaconda3\envs\env\lib\site-packages\werkzeug\routing\map.py", line 950, in build
    raise BuildError(endpoint, values, method, self)
werkzeug.routing.exceptions.BuildError: Could not build url for endpoint 'predictdata'. Did you mean 'predict_datapoint' instead?
[ 2023-08-12 11:25:36,906 ] 187 werkzeug - INFO - 127.0.0.1 - - [12/Aug/2023 11:25:36] "[35m[1mGET / HTTP/1.1[0m" 500 -
[ 2023-08-12 11:25:37,030 ] 187 werkzeug - INFO - 127.0.0.1 - - [12/Aug/2023 11:25:37] "[33mGET /favicon.ico HTTP/1.1[0m" 404 -
[ 2023-08-12 11:25:40,740 ] 1414 app - ERROR - Exception on / [GET]
Traceback (most recent call last):
  File "C:\Users\bhara\anaconda3\envs\env\lib\site-packages\flask\app.py", line 2190, in wsgi_app
    response = self.full_dispatch_request()
  File "C:\Users\bhara\anaconda3\envs\env\lib\site-packages\flask\app.py", line 1486, in full_dispatch_request
    rv = self.handle_user_exception(e)
  File "C:\Users\bhara\anaconda3\envs\env\lib\site-packages\flask\app.py", line 1484, in full_dispatch_request
    rv = self.dispatch_request()
  File "C:\Users\bhara\anaconda3\envs\env\lib\site-packages\flask\app.py", line 1469, in dispatch_request
    return self.ensure_sync(self.view_functions[rule.endpoint])(**view_args)
  File "app.py", line 11, in index
    return render_template('index.html')
  File "C:\Users\bhara\anaconda3\envs\env\lib\site-packages\flask\templating.py", line 151, in render_template
    return _render(app, template, context)
  File "C:\Users\bhara\anaconda3\envs\env\lib\site-packages\flask\templating.py", line 132, in _render
    rv = template.render(context)
  File "C:\Users\bhara\anaconda3\envs\env\lib\site-packages\jinja2\environment.py", line 1301, in render
    self.environment.handle_exception()
  File "C:\Users\bhara\anaconda3\envs\env\lib\site-packages\jinja2\environment.py", line 936, in handle_exception
    raise rewrite_traceback_stack(source=source)
  File "C:\Users\bhara\Downloads\newproject car modular1\templates\index.html", line 6, in top-level template code
    <form action="{{ url_for('predictdata')}}" method="post">
  File "C:\Users\bhara\anaconda3\envs\env\lib\site-packages\flask\app.py", line 1697, in url_for
    return self.handle_url_build_error(error, endpoint, values)
  File "C:\Users\bhara\anaconda3\envs\env\lib\site-packages\flask\app.py", line 1686, in url_for
    rv = url_adapter.build(  # type: ignore[union-attr]
  File "C:\Users\bhara\anaconda3\envs\env\lib\site-packages\werkzeug\routing\map.py", line 950, in build
    raise BuildError(endpoint, values, method, self)
werkzeug.routing.exceptions.BuildError: Could not build url for endpoint 'predictdata'. Did you mean 'predict_datapoint' instead?
[ 2023-08-12 11:25:40,740 ] 187 werkzeug - INFO - 127.0.0.1 - - [12/Aug/2023 11:25:40] "[35m[1mGET / HTTP/1.1[0m" 500 -
[ 2023-08-12 11:29:39,282 ] 1414 app - ERROR - Exception on / [GET]
Traceback (most recent call last):
  File "C:\Users\bhara\anaconda3\envs\env\lib\site-packages\flask\app.py", line 2190, in wsgi_app
    response = self.full_dispatch_request()
  File "C:\Users\bhara\anaconda3\envs\env\lib\site-packages\flask\app.py", line 1486, in full_dispatch_request
    rv = self.handle_user_exception(e)
  File "C:\Users\bhara\anaconda3\envs\env\lib\site-packages\flask\app.py", line 1484, in full_dispatch_request
    rv = self.dispatch_request()
  File "C:\Users\bhara\anaconda3\envs\env\lib\site-packages\flask\app.py", line 1469, in dispatch_request
    return self.ensure_sync(self.view_functions[rule.endpoint])(**view_args)
  File "app.py", line 11, in index
    @app.route('/')
  File "C:\Users\bhara\anaconda3\envs\env\lib\site-packages\flask\templating.py", line 151, in render_template
    return _render(app, template, context)
  File "C:\Users\bhara\anaconda3\envs\env\lib\site-packages\flask\templating.py", line 132, in _render
    rv = template.render(context)
  File "C:\Users\bhara\anaconda3\envs\env\lib\site-packages\jinja2\environment.py", line 1301, in render
    self.environment.handle_exception()
  File "C:\Users\bhara\anaconda3\envs\env\lib\site-packages\jinja2\environment.py", line 936, in handle_exception
    raise rewrite_traceback_stack(source=source)
  File "C:\Users\bhara\Downloads\newproject car modular1\templates\index.html", line 6, in top-level template code
    <form action="{{ url_for('predict_datapoint')}}" method="post">
  File "C:\Users\bhara\anaconda3\envs\env\lib\site-packages\flask\app.py", line 1697, in url_for
    return self.handle_url_build_error(error, endpoint, values)
  File "C:\Users\bhara\anaconda3\envs\env\lib\site-packages\flask\app.py", line 1686, in url_for
    rv = url_adapter.build(  # type: ignore[union-attr]
  File "C:\Users\bhara\anaconda3\envs\env\lib\site-packages\werkzeug\routing\map.py", line 950, in build
    raise BuildError(endpoint, values, method, self)
werkzeug.routing.exceptions.BuildError: Could not build url for endpoint 'predictdata'. Did you mean 'predict_datapoint' instead?
[ 2023-08-12 11:29:39,299 ] 187 werkzeug - INFO - 127.0.0.1 - - [12/Aug/2023 11:29:39] "[35m[1mGET / HTTP/1.1[0m" 500 -
[ 2023-08-12 11:29:40,982 ] 1414 app - ERROR - Exception on / [GET]
Traceback (most recent call last):
  File "C:\Users\bhara\anaconda3\envs\env\lib\site-packages\flask\app.py", line 2190, in wsgi_app
    response = self.full_dispatch_request()
  File "C:\Users\bhara\anaconda3\envs\env\lib\site-packages\flask\app.py", line 1486, in full_dispatch_request
    rv = self.handle_user_exception(e)
  File "C:\Users\bhara\anaconda3\envs\env\lib\site-packages\flask\app.py", line 1484, in full_dispatch_request
    rv = self.dispatch_request()
  File "C:\Users\bhara\anaconda3\envs\env\lib\site-packages\flask\app.py", line 1469, in dispatch_request
    return self.ensure_sync(self.view_functions[rule.endpoint])(**view_args)
  File "app.py", line 11, in index
    @app.route('/')
  File "C:\Users\bhara\anaconda3\envs\env\lib\site-packages\flask\templating.py", line 151, in render_template
    return _render(app, template, context)
  File "C:\Users\bhara\anaconda3\envs\env\lib\site-packages\flask\templating.py", line 132, in _render
    rv = template.render(context)
  File "C:\Users\bhara\anaconda3\envs\env\lib\site-packages\jinja2\environment.py", line 1301, in render
    self.environment.handle_exception()
  File "C:\Users\bhara\anaconda3\envs\env\lib\site-packages\jinja2\environment.py", line 936, in handle_exception
    raise rewrite_traceback_stack(source=source)
  File "C:\Users\bhara\Downloads\newproject car modular1\templates\index.html", line 6, in top-level template code
    <form action="{{ url_for('predict_datapoint')}}" method="post">
  File "C:\Users\bhara\anaconda3\envs\env\lib\site-packages\flask\app.py", line 1697, in url_for
    return self.handle_url_build_error(error, endpoint, values)
  File "C:\Users\bhara\anaconda3\envs\env\lib\site-packages\flask\app.py", line 1686, in url_for
    rv = url_adapter.build(  # type: ignore[union-attr]
  File "C:\Users\bhara\anaconda3\envs\env\lib\site-packages\werkzeug\routing\map.py", line 950, in build
    raise BuildError(endpoint, values, method, self)
werkzeug.routing.exceptions.BuildError: Could not build url for endpoint 'predictdata'. Did you mean 'predict_datapoint' instead?
[ 2023-08-12 11:29:40,985 ] 187 werkzeug - INFO - 127.0.0.1 - - [12/Aug/2023 11:29:40] "[35m[1mGET / HTTP/1.1[0m" 500 -
[ 2023-08-12 11:29:41,182 ] 1414 app - ERROR - Exception on / [GET]
Traceback (most recent call last):
  File "C:\Users\bhara\anaconda3\envs\env\lib\site-packages\flask\app.py", line 2190, in wsgi_app
    response = self.full_dispatch_request()
  File "C:\Users\bhara\anaconda3\envs\env\lib\site-packages\flask\app.py", line 1486, in full_dispatch_request
    rv = self.handle_user_exception(e)
  File "C:\Users\bhara\anaconda3\envs\env\lib\site-packages\flask\app.py", line 1484, in full_dispatch_request
    rv = self.dispatch_request()
  File "C:\Users\bhara\anaconda3\envs\env\lib\site-packages\flask\app.py", line 1469, in dispatch_request
    return self.ensure_sync(self.view_functions[rule.endpoint])(**view_args)
  File "app.py", line 11, in index
    @app.route('/')
  File "C:\Users\bhara\anaconda3\envs\env\lib\site-packages\flask\templating.py", line 151, in render_template
    return _render(app, template, context)
  File "C:\Users\bhara\anaconda3\envs\env\lib\site-packages\flask\templating.py", line 132, in _render
    rv = template.render(context)
  File "C:\Users\bhara\anaconda3\envs\env\lib\site-packages\jinja2\environment.py", line 1301, in render
    self.environment.handle_exception()
  File "C:\Users\bhara\anaconda3\envs\env\lib\site-packages\jinja2\environment.py", line 936, in handle_exception
    raise rewrite_traceback_stack(source=source)
  File "C:\Users\bhara\Downloads\newproject car modular1\templates\index.html", line 6, in top-level template code
    <form action="{{ url_for('predict_datapoint')}}" method="post">
  File "C:\Users\bhara\anaconda3\envs\env\lib\site-packages\flask\app.py", line 1697, in url_for
    return self.handle_url_build_error(error, endpoint, values)
  File "C:\Users\bhara\anaconda3\envs\env\lib\site-packages\flask\app.py", line 1686, in url_for
    rv = url_adapter.build(  # type: ignore[union-attr]
  File "C:\Users\bhara\anaconda3\envs\env\lib\site-packages\werkzeug\routing\map.py", line 950, in build
    raise BuildError(endpoint, values, method, self)
werkzeug.routing.exceptions.BuildError: Could not build url for endpoint 'predictdata'. Did you mean 'predict_datapoint' instead?
[ 2023-08-12 11:29:41,184 ] 187 werkzeug - INFO - 127.0.0.1 - - [12/Aug/2023 11:29:41] "[35m[1mGET / HTTP/1.1[0m" 500 -
[ 2023-08-12 11:29:41,440 ] 1414 app - ERROR - Exception on / [GET]
Traceback (most recent call last):
  File "C:\Users\bhara\anaconda3\envs\env\lib\site-packages\flask\app.py", line 2190, in wsgi_app
    response = self.full_dispatch_request()
  File "C:\Users\bhara\anaconda3\envs\env\lib\site-packages\flask\app.py", line 1486, in full_dispatch_request
    rv = self.handle_user_exception(e)
  File "C:\Users\bhara\anaconda3\envs\env\lib\site-packages\flask\app.py", line 1484, in full_dispatch_request
    rv = self.dispatch_request()
  File "C:\Users\bhara\anaconda3\envs\env\lib\site-packages\flask\app.py", line 1469, in dispatch_request
    return self.ensure_sync(self.view_functions[rule.endpoint])(**view_args)
  File "app.py", line 11, in index
    @app.route('/')
  File "C:\Users\bhara\anaconda3\envs\env\lib\site-packages\flask\templating.py", line 151, in render_template
    return _render(app, template, context)
  File "C:\Users\bhara\anaconda3\envs\env\lib\site-packages\flask\templating.py", line 132, in _render
    rv = template.render(context)
  File "C:\Users\bhara\anaconda3\envs\env\lib\site-packages\jinja2\environment.py", line 1301, in render
    self.environment.handle_exception()
  File "C:\Users\bhara\anaconda3\envs\env\lib\site-packages\jinja2\environment.py", line 936, in handle_exception
    raise rewrite_traceback_stack(source=source)
  File "C:\Users\bhara\Downloads\newproject car modular1\templates\index.html", line 6, in top-level template code
    <form action="{{ url_for('predict_datapoint')}}" method="post">
  File "C:\Users\bhara\anaconda3\envs\env\lib\site-packages\flask\app.py", line 1697, in url_for
    return self.handle_url_build_error(error, endpoint, values)
  File "C:\Users\bhara\anaconda3\envs\env\lib\site-packages\flask\app.py", line 1686, in url_for
    rv = url_adapter.build(  # type: ignore[union-attr]
  File "C:\Users\bhara\anaconda3\envs\env\lib\site-packages\werkzeug\routing\map.py", line 950, in build
    raise BuildError(endpoint, values, method, self)
werkzeug.routing.exceptions.BuildError: Could not build url for endpoint 'predictdata'. Did you mean 'predict_datapoint' instead?
[ 2023-08-12 11:29:41,440 ] 187 werkzeug - INFO - 127.0.0.1 - - [12/Aug/2023 11:29:41] "[35m[1mGET / HTTP/1.1[0m" 500 -
[ 2023-08-12 11:29:41,584 ] 1414 app - ERROR - Exception on / [GET]
Traceback (most recent call last):
  File "C:\Users\bhara\anaconda3\envs\env\lib\site-packages\flask\app.py", line 2190, in wsgi_app
    response = self.full_dispatch_request()
  File "C:\Users\bhara\anaconda3\envs\env\lib\site-packages\flask\app.py", line 1486, in full_dispatch_request
    rv = self.handle_user_exception(e)
  File "C:\Users\bhara\anaconda3\envs\env\lib\site-packages\flask\app.py", line 1484, in full_dispatch_request
    rv = self.dispatch_request()
  File "C:\Users\bhara\anaconda3\envs\env\lib\site-packages\flask\app.py", line 1469, in dispatch_request
    return self.ensure_sync(self.view_functions[rule.endpoint])(**view_args)
  File "app.py", line 11, in index
    @app.route('/')
  File "C:\Users\bhara\anaconda3\envs\env\lib\site-packages\flask\templating.py", line 151, in render_template
    return _render(app, template, context)
  File "C:\Users\bhara\anaconda3\envs\env\lib\site-packages\flask\templating.py", line 132, in _render
    rv = template.render(context)
  File "C:\Users\bhara\anaconda3\envs\env\lib\site-packages\jinja2\environment.py", line 1301, in render
    self.environment.handle_exception()
  File "C:\Users\bhara\anaconda3\envs\env\lib\site-packages\jinja2\environment.py", line 936, in handle_exception
    raise rewrite_traceback_stack(source=source)
  File "C:\Users\bhara\Downloads\newproject car modular1\templates\index.html", line 6, in top-level template code
    <form action="{{ url_for('predict_datapoint')}}" method="post">
  File "C:\Users\bhara\anaconda3\envs\env\lib\site-packages\flask\app.py", line 1697, in url_for
    return self.handle_url_build_error(error, endpoint, values)
  File "C:\Users\bhara\anaconda3\envs\env\lib\site-packages\flask\app.py", line 1686, in url_for
    rv = url_adapter.build(  # type: ignore[union-attr]
  File "C:\Users\bhara\anaconda3\envs\env\lib\site-packages\werkzeug\routing\map.py", line 950, in build
    raise BuildError(endpoint, values, method, self)
werkzeug.routing.exceptions.BuildError: Could not build url for endpoint 'predictdata'. Did you mean 'predict_datapoint' instead?
[ 2023-08-12 11:29:41,600 ] 187 werkzeug - INFO - 127.0.0.1 - - [12/Aug/2023 11:29:41] "[35m[1mGET / HTTP/1.1[0m" 500 -
[ 2023-08-12 11:29:41,814 ] 1414 app - ERROR - Exception on / [GET]
Traceback (most recent call last):
  File "C:\Users\bhara\anaconda3\envs\env\lib\site-packages\flask\app.py", line 2190, in wsgi_app
    response = self.full_dispatch_request()
  File "C:\Users\bhara\anaconda3\envs\env\lib\site-packages\flask\app.py", line 1486, in full_dispatch_request
    rv = self.handle_user_exception(e)
  File "C:\Users\bhara\anaconda3\envs\env\lib\site-packages\flask\app.py", line 1484, in full_dispatch_request
    rv = self.dispatch_request()
  File "C:\Users\bhara\anaconda3\envs\env\lib\site-packages\flask\app.py", line 1469, in dispatch_request
    return self.ensure_sync(self.view_functions[rule.endpoint])(**view_args)
  File "app.py", line 11, in index
    @app.route('/')
  File "C:\Users\bhara\anaconda3\envs\env\lib\site-packages\flask\templating.py", line 151, in render_template
    return _render(app, template, context)
  File "C:\Users\bhara\anaconda3\envs\env\lib\site-packages\flask\templating.py", line 132, in _render
    rv = template.render(context)
  File "C:\Users\bhara\anaconda3\envs\env\lib\site-packages\jinja2\environment.py", line 1301, in render
    self.environment.handle_exception()
  File "C:\Users\bhara\anaconda3\envs\env\lib\site-packages\jinja2\environment.py", line 936, in handle_exception
    raise rewrite_traceback_stack(source=source)
  File "C:\Users\bhara\Downloads\newproject car modular1\templates\index.html", line 6, in top-level template code
    <form action="{{ url_for('predict_datapoint')}}" method="post">
  File "C:\Users\bhara\anaconda3\envs\env\lib\site-packages\flask\app.py", line 1697, in url_for
    return self.handle_url_build_error(error, endpoint, values)
  File "C:\Users\bhara\anaconda3\envs\env\lib\site-packages\flask\app.py", line 1686, in url_for
    rv = url_adapter.build(  # type: ignore[union-attr]
  File "C:\Users\bhara\anaconda3\envs\env\lib\site-packages\werkzeug\routing\map.py", line 950, in build
    raise BuildError(endpoint, values, method, self)
werkzeug.routing.exceptions.BuildError: Could not build url for endpoint 'predictdata'. Did you mean 'predict_datapoint' instead?
[ 2023-08-12 11:29:41,814 ] 187 werkzeug - INFO - 127.0.0.1 - - [12/Aug/2023 11:29:41] "[35m[1mGET / HTTP/1.1[0m" 500 -
[ 2023-08-12 11:29:41,968 ] 1414 app - ERROR - Exception on / [GET]
Traceback (most recent call last):
  File "C:\Users\bhara\anaconda3\envs\env\lib\site-packages\flask\app.py", line 2190, in wsgi_app
    response = self.full_dispatch_request()
  File "C:\Users\bhara\anaconda3\envs\env\lib\site-packages\flask\app.py", line 1486, in full_dispatch_request
    rv = self.handle_user_exception(e)
  File "C:\Users\bhara\anaconda3\envs\env\lib\site-packages\flask\app.py", line 1484, in full_dispatch_request
    rv = self.dispatch_request()
  File "C:\Users\bhara\anaconda3\envs\env\lib\site-packages\flask\app.py", line 1469, in dispatch_request
    return self.ensure_sync(self.view_functions[rule.endpoint])(**view_args)
  File "app.py", line 11, in index
    @app.route('/')
  File "C:\Users\bhara\anaconda3\envs\env\lib\site-packages\flask\templating.py", line 151, in render_template
    return _render(app, template, context)
  File "C:\Users\bhara\anaconda3\envs\env\lib\site-packages\flask\templating.py", line 132, in _render
    rv = template.render(context)
  File "C:\Users\bhara\anaconda3\envs\env\lib\site-packages\jinja2\environment.py", line 1301, in render
    self.environment.handle_exception()
  File "C:\Users\bhara\anaconda3\envs\env\lib\site-packages\jinja2\environment.py", line 936, in handle_exception
    raise rewrite_traceback_stack(source=source)
  File "C:\Users\bhara\Downloads\newproject car modular1\templates\index.html", line 6, in top-level template code
    <form action="{{ url_for('predict_datapoint')}}" method="post">
  File "C:\Users\bhara\anaconda3\envs\env\lib\site-packages\flask\app.py", line 1697, in url_for
    return self.handle_url_build_error(error, endpoint, values)
  File "C:\Users\bhara\anaconda3\envs\env\lib\site-packages\flask\app.py", line 1686, in url_for
    rv = url_adapter.build(  # type: ignore[union-attr]
  File "C:\Users\bhara\anaconda3\envs\env\lib\site-packages\werkzeug\routing\map.py", line 950, in build
    raise BuildError(endpoint, values, method, self)
werkzeug.routing.exceptions.BuildError: Could not build url for endpoint 'predictdata'. Did you mean 'predict_datapoint' instead?
[ 2023-08-12 11:29:41,969 ] 187 werkzeug - INFO - 127.0.0.1 - - [12/Aug/2023 11:29:41] "[35m[1mGET / HTTP/1.1[0m" 500 -
[ 2023-08-12 11:30:14,021 ] 1414 app - ERROR - Exception on / [GET]
Traceback (most recent call last):
  File "C:\Users\bhara\anaconda3\envs\env\lib\site-packages\flask\app.py", line 2190, in wsgi_app
    response = self.full_dispatch_request()
  File "C:\Users\bhara\anaconda3\envs\env\lib\site-packages\flask\app.py", line 1486, in full_dispatch_request
    rv = self.handle_user_exception(e)
  File "C:\Users\bhara\anaconda3\envs\env\lib\site-packages\flask\app.py", line 1484, in full_dispatch_request
    rv = self.dispatch_request()
  File "C:\Users\bhara\anaconda3\envs\env\lib\site-packages\flask\app.py", line 1469, in dispatch_request
    return self.ensure_sync(self.view_functions[rule.endpoint])(**view_args)
  File "app.py", line 11, in index
    @app.route('/')
  File "C:\Users\bhara\anaconda3\envs\env\lib\site-packages\flask\templating.py", line 151, in render_template
    return _render(app, template, context)
  File "C:\Users\bhara\anaconda3\envs\env\lib\site-packages\flask\templating.py", line 132, in _render
    rv = template.render(context)
  File "C:\Users\bhara\anaconda3\envs\env\lib\site-packages\jinja2\environment.py", line 1301, in render
    self.environment.handle_exception()
  File "C:\Users\bhara\anaconda3\envs\env\lib\site-packages\jinja2\environment.py", line 936, in handle_exception
    raise rewrite_traceback_stack(source=source)
  File "C:\Users\bhara\Downloads\newproject car modular1\templates\index.html", line 6, in top-level template code
    <form action="{{ url_for('predict_datapoint')}}" method="post">
  File "C:\Users\bhara\anaconda3\envs\env\lib\site-packages\flask\app.py", line 1697, in url_for
    return self.handle_url_build_error(error, endpoint, values)
  File "C:\Users\bhara\anaconda3\envs\env\lib\site-packages\flask\app.py", line 1686, in url_for
    rv = url_adapter.build(  # type: ignore[union-attr]
  File "C:\Users\bhara\anaconda3\envs\env\lib\site-packages\werkzeug\routing\map.py", line 950, in build
    raise BuildError(endpoint, values, method, self)
werkzeug.routing.exceptions.BuildError: Could not build url for endpoint 'predictdata'. Did you mean 'predict_datapoint' instead?
[ 2023-08-12 11:30:14,021 ] 187 werkzeug - INFO - 127.0.0.1 - - [12/Aug/2023 11:30:14] "[35m[1mGET / HTTP/1.1[0m" 500 -
[ 2023-08-12 11:30:15,134 ] 1414 app - ERROR - Exception on / [GET]
Traceback (most recent call last):
  File "C:\Users\bhara\anaconda3\envs\env\lib\site-packages\flask\app.py", line 2190, in wsgi_app
    response = self.full_dispatch_request()
  File "C:\Users\bhara\anaconda3\envs\env\lib\site-packages\flask\app.py", line 1486, in full_dispatch_request
    rv = self.handle_user_exception(e)
  File "C:\Users\bhara\anaconda3\envs\env\lib\site-packages\flask\app.py", line 1484, in full_dispatch_request
    rv = self.dispatch_request()
  File "C:\Users\bhara\anaconda3\envs\env\lib\site-packages\flask\app.py", line 1469, in dispatch_request
    return self.ensure_sync(self.view_functions[rule.endpoint])(**view_args)
  File "app.py", line 11, in index
    @app.route('/')
  File "C:\Users\bhara\anaconda3\envs\env\lib\site-packages\flask\templating.py", line 151, in render_template
    return _render(app, template, context)
  File "C:\Users\bhara\anaconda3\envs\env\lib\site-packages\flask\templating.py", line 132, in _render
    rv = template.render(context)
  File "C:\Users\bhara\anaconda3\envs\env\lib\site-packages\jinja2\environment.py", line 1301, in render
    self.environment.handle_exception()
  File "C:\Users\bhara\anaconda3\envs\env\lib\site-packages\jinja2\environment.py", line 936, in handle_exception
    raise rewrite_traceback_stack(source=source)
  File "C:\Users\bhara\Downloads\newproject car modular1\templates\index.html", line 6, in top-level template code
    <form action="{{ url_for('predict_datapoint')}}" method="post">
  File "C:\Users\bhara\anaconda3\envs\env\lib\site-packages\flask\app.py", line 1697, in url_for
    return self.handle_url_build_error(error, endpoint, values)
  File "C:\Users\bhara\anaconda3\envs\env\lib\site-packages\flask\app.py", line 1686, in url_for
    rv = url_adapter.build(  # type: ignore[union-attr]
  File "C:\Users\bhara\anaconda3\envs\env\lib\site-packages\werkzeug\routing\map.py", line 950, in build
    raise BuildError(endpoint, values, method, self)
werkzeug.routing.exceptions.BuildError: Could not build url for endpoint 'predictdata'. Did you mean 'predict_datapoint' instead?
[ 2023-08-12 11:30:15,141 ] 187 werkzeug - INFO - 127.0.0.1 - - [12/Aug/2023 11:30:15] "[35m[1mGET / HTTP/1.1[0m" 500 -
[ 2023-08-12 11:30:15,334 ] 1414 app - ERROR - Exception on / [GET]
Traceback (most recent call last):
  File "C:\Users\bhara\anaconda3\envs\env\lib\site-packages\flask\app.py", line 2190, in wsgi_app
    response = self.full_dispatch_request()
  File "C:\Users\bhara\anaconda3\envs\env\lib\site-packages\flask\app.py", line 1486, in full_dispatch_request
    rv = self.handle_user_exception(e)
  File "C:\Users\bhara\anaconda3\envs\env\lib\site-packages\flask\app.py", line 1484, in full_dispatch_request
    rv = self.dispatch_request()
  File "C:\Users\bhara\anaconda3\envs\env\lib\site-packages\flask\app.py", line 1469, in dispatch_request
    return self.ensure_sync(self.view_functions[rule.endpoint])(**view_args)
  File "app.py", line 11, in index
    @app.route('/')
  File "C:\Users\bhara\anaconda3\envs\env\lib\site-packages\flask\templating.py", line 151, in render_template
    return _render(app, template, context)
  File "C:\Users\bhara\anaconda3\envs\env\lib\site-packages\flask\templating.py", line 132, in _render
    rv = template.render(context)
  File "C:\Users\bhara\anaconda3\envs\env\lib\site-packages\jinja2\environment.py", line 1301, in render
    self.environment.handle_exception()
  File "C:\Users\bhara\anaconda3\envs\env\lib\site-packages\jinja2\environment.py", line 936, in handle_exception
    raise rewrite_traceback_stack(source=source)
  File "C:\Users\bhara\Downloads\newproject car modular1\templates\index.html", line 6, in top-level template code
    <form action="{{ url_for('predict_datapoint')}}" method="post">
  File "C:\Users\bhara\anaconda3\envs\env\lib\site-packages\flask\app.py", line 1697, in url_for
    return self.handle_url_build_error(error, endpoint, values)
  File "C:\Users\bhara\anaconda3\envs\env\lib\site-packages\flask\app.py", line 1686, in url_for
    rv = url_adapter.build(  # type: ignore[union-attr]
  File "C:\Users\bhara\anaconda3\envs\env\lib\site-packages\werkzeug\routing\map.py", line 950, in build
    raise BuildError(endpoint, values, method, self)
werkzeug.routing.exceptions.BuildError: Could not build url for endpoint 'predictdata'. Did you mean 'predict_datapoint' instead?
[ 2023-08-12 11:30:15,340 ] 187 werkzeug - INFO - 127.0.0.1 - - [12/Aug/2023 11:30:15] "[35m[1mGET / HTTP/1.1[0m" 500 -
[ 2023-08-12 11:30:15,690 ] 1414 app - ERROR - Exception on / [GET]
Traceback (most recent call last):
  File "C:\Users\bhara\anaconda3\envs\env\lib\site-packages\flask\app.py", line 2190, in wsgi_app
    response = self.full_dispatch_request()
  File "C:\Users\bhara\anaconda3\envs\env\lib\site-packages\flask\app.py", line 1486, in full_dispatch_request
    rv = self.handle_user_exception(e)
  File "C:\Users\bhara\anaconda3\envs\env\lib\site-packages\flask\app.py", line 1484, in full_dispatch_request
    rv = self.dispatch_request()
  File "C:\Users\bhara\anaconda3\envs\env\lib\site-packages\flask\app.py", line 1469, in dispatch_request
    return self.ensure_sync(self.view_functions[rule.endpoint])(**view_args)
  File "app.py", line 11, in index
    @app.route('/')
  File "C:\Users\bhara\anaconda3\envs\env\lib\site-packages\flask\templating.py", line 151, in render_template
    return _render(app, template, context)
  File "C:\Users\bhara\anaconda3\envs\env\lib\site-packages\flask\templating.py", line 132, in _render
    rv = template.render(context)
  File "C:\Users\bhara\anaconda3\envs\env\lib\site-packages\jinja2\environment.py", line 1301, in render
    self.environment.handle_exception()
  File "C:\Users\bhara\anaconda3\envs\env\lib\site-packages\jinja2\environment.py", line 936, in handle_exception
    raise rewrite_traceback_stack(source=source)
  File "C:\Users\bhara\Downloads\newproject car modular1\templates\index.html", line 6, in top-level template code
    <form action="{{ url_for('predict_datapoint')}}" method="post">
  File "C:\Users\bhara\anaconda3\envs\env\lib\site-packages\flask\app.py", line 1697, in url_for
    return self.handle_url_build_error(error, endpoint, values)
  File "C:\Users\bhara\anaconda3\envs\env\lib\site-packages\flask\app.py", line 1686, in url_for
    rv = url_adapter.build(  # type: ignore[union-attr]
  File "C:\Users\bhara\anaconda3\envs\env\lib\site-packages\werkzeug\routing\map.py", line 950, in build
    raise BuildError(endpoint, values, method, self)
werkzeug.routing.exceptions.BuildError: Could not build url for endpoint 'predictdata'. Did you mean 'predict_datapoint' instead?
[ 2023-08-12 11:30:15,706 ] 187 werkzeug - INFO - 127.0.0.1 - - [12/Aug/2023 11:30:15] "[35m[1mGET / HTTP/1.1[0m" 500 -
[ 2023-08-12 11:30:15,748 ] 1414 app - ERROR - Exception on / [GET]
Traceback (most recent call last):
  File "C:\Users\bhara\anaconda3\envs\env\lib\site-packages\flask\app.py", line 2190, in wsgi_app
    response = self.full_dispatch_request()
  File "C:\Users\bhara\anaconda3\envs\env\lib\site-packages\flask\app.py", line 1486, in full_dispatch_request
    rv = self.handle_user_exception(e)
  File "C:\Users\bhara\anaconda3\envs\env\lib\site-packages\flask\app.py", line 1484, in full_dispatch_request
    rv = self.dispatch_request()
  File "C:\Users\bhara\anaconda3\envs\env\lib\site-packages\flask\app.py", line 1469, in dispatch_request
    return self.ensure_sync(self.view_functions[rule.endpoint])(**view_args)
  File "app.py", line 11, in index
    @app.route('/')
  File "C:\Users\bhara\anaconda3\envs\env\lib\site-packages\flask\templating.py", line 151, in render_template
    return _render(app, template, context)
  File "C:\Users\bhara\anaconda3\envs\env\lib\site-packages\flask\templating.py", line 132, in _render
    rv = template.render(context)
  File "C:\Users\bhara\anaconda3\envs\env\lib\site-packages\jinja2\environment.py", line 1301, in render
    self.environment.handle_exception()
  File "C:\Users\bhara\anaconda3\envs\env\lib\site-packages\jinja2\environment.py", line 936, in handle_exception
    raise rewrite_traceback_stack(source=source)
  File "C:\Users\bhara\Downloads\newproject car modular1\templates\index.html", line 6, in top-level template code
    <form action="{{ url_for('predict_datapoint')}}" method="post">
  File "C:\Users\bhara\anaconda3\envs\env\lib\site-packages\flask\app.py", line 1697, in url_for
    return self.handle_url_build_error(error, endpoint, values)
  File "C:\Users\bhara\anaconda3\envs\env\lib\site-packages\flask\app.py", line 1686, in url_for
    rv = url_adapter.build(  # type: ignore[union-attr]
  File "C:\Users\bhara\anaconda3\envs\env\lib\site-packages\werkzeug\routing\map.py", line 950, in build
    raise BuildError(endpoint, values, method, self)
werkzeug.routing.exceptions.BuildError: Could not build url for endpoint 'predictdata'. Did you mean 'predict_datapoint' instead?
[ 2023-08-12 11:30:15,750 ] 187 werkzeug - INFO - 127.0.0.1 - - [12/Aug/2023 11:30:15] "[35m[1mGET / HTTP/1.1[0m" 500 -
[ 2023-08-12 11:30:19,162 ] 1414 app - ERROR - Exception on /predictdata [GET]
Traceback (most recent call last):
  File "C:\Users\bhara\anaconda3\envs\env\lib\site-packages\flask\app.py", line 2190, in wsgi_app
    response = self.full_dispatch_request()
  File "C:\Users\bhara\anaconda3\envs\env\lib\site-packages\flask\app.py", line 1486, in full_dispatch_request
    rv = self.handle_user_exception(e)
  File "C:\Users\bhara\anaconda3\envs\env\lib\site-packages\flask\app.py", line 1484, in full_dispatch_request
    rv = self.dispatch_request()
  File "C:\Users\bhara\anaconda3\envs\env\lib\site-packages\flask\app.py", line 1469, in dispatch_request
    return self.ensure_sync(self.view_functions[rule.endpoint])(**view_args)
  File "app.py", line 16, in predict_datapoint
    def predict_datapoint():
  File "C:\Users\bhara\anaconda3\envs\env\lib\site-packages\flask\templating.py", line 151, in render_template
    return _render(app, template, context)
  File "C:\Users\bhara\anaconda3\envs\env\lib\site-packages\flask\templating.py", line 132, in _render
    rv = template.render(context)
  File "C:\Users\bhara\anaconda3\envs\env\lib\site-packages\jinja2\environment.py", line 1301, in render
    self.environment.handle_exception()
  File "C:\Users\bhara\anaconda3\envs\env\lib\site-packages\jinja2\environment.py", line 936, in handle_exception
    raise rewrite_traceback_stack(source=source)
  File "C:\Users\bhara\Downloads\newproject car modular1\templates\index.html", line 6, in top-level template code
    <form action="{{ url_for('predict_datapoint')}}" method="post">
  File "C:\Users\bhara\anaconda3\envs\env\lib\site-packages\flask\app.py", line 1697, in url_for
    return self.handle_url_build_error(error, endpoint, values)
  File "C:\Users\bhara\anaconda3\envs\env\lib\site-packages\flask\app.py", line 1686, in url_for
    rv = url_adapter.build(  # type: ignore[union-attr]
  File "C:\Users\bhara\anaconda3\envs\env\lib\site-packages\werkzeug\routing\map.py", line 950, in build
    raise BuildError(endpoint, values, method, self)
werkzeug.routing.exceptions.BuildError: Could not build url for endpoint 'predictdata'. Did you mean 'predict_datapoint' instead?
[ 2023-08-12 11:30:19,166 ] 187 werkzeug - INFO - 127.0.0.1 - - [12/Aug/2023 11:30:19] "[35m[1mGET /predictdata HTTP/1.1[0m" 500 -
[ 2023-08-12 11:30:22,862 ] 1414 app - ERROR - Exception on /predictdata [GET]
Traceback (most recent call last):
  File "C:\Users\bhara\anaconda3\envs\env\lib\site-packages\flask\app.py", line 2190, in wsgi_app
    response = self.full_dispatch_request()
  File "C:\Users\bhara\anaconda3\envs\env\lib\site-packages\flask\app.py", line 1486, in full_dispatch_request
    rv = self.handle_user_exception(e)
  File "C:\Users\bhara\anaconda3\envs\env\lib\site-packages\flask\app.py", line 1484, in full_dispatch_request
    rv = self.dispatch_request()
  File "C:\Users\bhara\anaconda3\envs\env\lib\site-packages\flask\app.py", line 1469, in dispatch_request
    return self.ensure_sync(self.view_functions[rule.endpoint])(**view_args)
  File "app.py", line 16, in predict_datapoint
    def predict_datapoint():
  File "C:\Users\bhara\anaconda3\envs\env\lib\site-packages\flask\templating.py", line 151, in render_template
    return _render(app, template, context)
  File "C:\Users\bhara\anaconda3\envs\env\lib\site-packages\flask\templating.py", line 132, in _render
    rv = template.render(context)
  File "C:\Users\bhara\anaconda3\envs\env\lib\site-packages\jinja2\environment.py", line 1301, in render
    self.environment.handle_exception()
  File "C:\Users\bhara\anaconda3\envs\env\lib\site-packages\jinja2\environment.py", line 936, in handle_exception
    raise rewrite_traceback_stack(source=source)
  File "C:\Users\bhara\Downloads\newproject car modular1\templates\index.html", line 6, in top-level template code
    <form action="{{ url_for('predict_datapoint')}}" method="post">
  File "C:\Users\bhara\anaconda3\envs\env\lib\site-packages\flask\app.py", line 1697, in url_for
    return self.handle_url_build_error(error, endpoint, values)
  File "C:\Users\bhara\anaconda3\envs\env\lib\site-packages\flask\app.py", line 1686, in url_for
    rv = url_adapter.build(  # type: ignore[union-attr]
  File "C:\Users\bhara\anaconda3\envs\env\lib\site-packages\werkzeug\routing\map.py", line 950, in build
    raise BuildError(endpoint, values, method, self)
werkzeug.routing.exceptions.BuildError: Could not build url for endpoint 'predictdata'. Did you mean 'predict_datapoint' instead?
[ 2023-08-12 11:30:22,862 ] 187 werkzeug - INFO - 127.0.0.1 - - [12/Aug/2023 11:30:22] "[35m[1mGET /predictdata HTTP/1.1[0m" 500 -
